(logai-py310) PS D:\logai-main\logai> python .\elastic_wrapper.py
Traceback (most recent call last):
  File "C:\Users\cg722v\Miniconda3\envs\logai-py310\lib\site-packages\pandas\core\indexes\base.py", line 3812, in get_loc
    return self._engine.get_loc(casted_key)
  File "pandas/_libs/index.pyx", line 167, in pandas._libs.index.IndexEngine.get_loc
  File "pandas/_libs/index.pyx", line 196, in pandas._libs.index.IndexEngine.get_loc
  File "pandas/_libs/hashtable_class_helper.pxi", line 7088, in pandas._libs.hashtable.PyObjectHashTable.get_item
  File "pandas/_libs/hashtable_class_helper.pxi", line 7096, in pandas._libs.hashtable.PyObjectHashTable.get_item
KeyError: 'features.tpl_hash'

The above exception was the direct cause of the following exception:

Traceback (most recent call last):
  File "D:\logai-main\logai\elastic_wrapper.py", line 106, in <module>
    df.groupby("features.tpl_hash")
  File "C:\Users\cg722v\Miniconda3\envs\logai-py310\lib\site-packages\pandas\core\frame.py", line 4107, in __getitem__
    indexer = self.columns.get_loc(key)
  File "C:\Users\cg722v\Miniconda3\envs\logai-py310\lib\site-packages\pandas\core\indexes\base.py", line 3819, in get_loc
    raise KeyError(key) from err
KeyError: 'features.tpl_hash'
